<?xml version="1.0" ?>
<!-- =================================================================================== -->
<!-- |    This document was autogenerated by xacro from panda_arm.urdf.xacro           | -->
<!-- |    EDITING THIS FILE BY HAND IS NOT RECOMMENDED                                 | -->
<!-- =================================================================================== -->
<robot name="panda">
  <link name="panda_link0">
    <visual>
      <geometry>
        <mesh filename="package://moveit_resources_franka_panda_description/meshes/visual/link0.dae"/>
      </geometry>
    </visual>
    <collision>
      <origin rpy="0 1.5707963267948966 0" xyz="-0.075 0 0.06"/>
      <geometry>
        <cylinder length="0.03" radius="0.09"/>
      </geometry>
    </collision>
    <collision>
      <origin rpy="0 0 0" xyz="-0.06 0 0.06"/>
      <geometry>
        <sphere radius="0.09"/>
      </geometry>
    </collision>
    <collision>
      <origin rpy="0 0 0" xyz="-0.09 0 0.06"/>
      <geometry>
        <sphere radius="0.09"/>
      </geometry>
    </collision>
  </link>
  <link name="panda_link1">
    <visual>
      <geometry>
        <mesh filename="package://moveit_resources_franka_panda_description/meshes/visual/link1.dae"/>
      </geometry>
    </visual>
    <collision>
      <origin rpy="0 0 0" xyz="0 0 -0.1915"/>
      <geometry>
        <cylinder length="0.2830" radius="0.09"/>
      </geometry>
    </collision>
    <collision>
      <origin rpy="0 0 0" xyz="0 0 -0.333"/>
      <geometry>
        <sphere radius="0.09"/>
      </geometry>
    </collision>
    <collision>
      <origin rpy="0 0 0" xyz="0 0 -0.05"/>
      <geometry>
        <sphere radius="0.09"/>
      </geometry>
    </collision>
  </link>
  <joint name="panda_joint1" type="revolute">
    <safety_controller k_position="100.0" k_velocity="40.0" soft_lower_limit="-2.8973" soft_upper_limit="2.8973"/>
    <origin rpy="0 0 0" xyz="0 0 0.333"/>
    <parent link="panda_link0"/>
    <child link="panda_link1"/>
    <axis xyz="0 0 1"/>
    <limit effort="87" lower="-2.8973" upper="2.8973" velocity="2.1750"/>
  </joint>
  <link name="panda_link2">
    <visual>
      <geometry>
        <mesh filename="package://moveit_resources_franka_panda_description/meshes/visual/link2.dae"/>
      </geometry>
    </visual>
    <collision>
      <origin rpy="0 0 0" xyz="0 0 0"/>
      <geometry>
        <cylinder length="0.12" radius="0.09"/>
      </geometry>
    </collision>
    <collision>
      <origin rpy="0 0 0" xyz="0 0 -0.06"/>
      <geometry>
        <sphere radius="0.09"/>
      </geometry>
    </collision>
    <collision>
      <origin rpy="0 0 0" xyz="0 0 0.06"/>
      <geometry>
        <sphere radius="0.09"/>
      </geometry>
    </collision>
  </link>
  <joint name="panda_joint2" type="revolute">
    <safety_controller k_position="100.0" k_velocity="40.0" soft_lower_limit="-1.7628" soft_upper_limit="1.7628"/>
    <origin rpy="-1.5707963267948966 0 0" xyz="0 0 0"/>
    <parent link="panda_link1"/>
    <child link="panda_link2"/>
    <axis xyz="0 0 1"/>
    <limit effort="87" lower="-1.7628" upper="1.7628" velocity="2.1750"/>
  </joint>
  <link name="panda_link3">
    <visual>
      <geometry>
        <mesh filename="package://moveit_resources_franka_panda_description/meshes/visual/link3.dae"/>
      </geometry>
    </visual>
    <collision>
      <origin rpy="0 0 0" xyz="0 0 -0.145"/>
      <geometry>
        <cylinder length="0.15" radius="0.09"/>
      </geometry>
    </collision>
    <collision>
      <origin rpy="0 0 0" xyz="0 0 -0.22"/>
      <geometry>
        <sphere radius="0.09"/>
      </geometry>
    </collision>
    <collision>
      <origin rpy="0 0 0" xyz="0 0 -0.07"/>
      <geometry>
        <sphere radius="0.09"/>
      </geometry>
    </collision>
  </link>
  <joint name="panda_joint3" type="revolute">
    <safety_controller k_position="100.0" k_velocity="40.0" soft_lower_limit="-2.8973" soft_upper_limit="2.8973"/>
    <origin rpy="1.5707963267948966 0 0" xyz="0 -0.316 0"/>
    <parent link="panda_link2"/>
    <child link="panda_link3"/>
    <axis xyz="0 0 1"/>
    <limit effort="87" lower="-2.8973" upper="2.8973" velocity="2.1750"/>
  </joint>
  <link name="panda_link4">
    <visual>
      <geometry>
        <mesh filename="package://moveit_resources_franka_panda_description/meshes/visual/link4.dae"/>
      </geometry>
    </visual>
    <collision>
      <origin rpy="0 0 0" xyz="0 0 0"/>
      <geometry>
        <cylinder length="0.12" radius="0.09"/>
      </geometry>
    </collision>
    <collision>
      <origin rpy="0 0 0" xyz="0 0 0.06"/>
      <geometry>
        <sphere radius="0.09"/>
      </geometry>
    </collision>
    <collision>
      <origin rpy="0 0 0" xyz="0 0 -0.06"/>
      <geometry>
        <sphere radius="0.09"/>
      </geometry>
    </collision>
  </link>
  <joint name="panda_joint4" type="revolute">
    <safety_controller k_position="100.0" k_velocity="40.0" soft_lower_limit="-3.0718" soft_upper_limit="-0.0698"/>
    <origin rpy="1.5707963267948966 0 0" xyz="0.0825 0 0"/>
    <parent link="panda_link3"/>
    <child link="panda_link4"/>
    <axis xyz="0 0 1"/>
    <limit effort="87" lower="-3.0718" upper="-0.0698" velocity="2.1750"/>
  </joint>
  <link name="panda_link5">
    <visual>
      <geometry>
        <mesh filename="package://moveit_resources_franka_panda_description/meshes/visual/link5.dae"/>
      </geometry>
    </visual>
    <collision>
      <origin rpy="0 0 0" xyz="0 0 -0.26"/>
      <geometry>
        <cylinder length="0.1" radius="0.09"/>
      </geometry>
    </collision>
    <collision>
      <origin rpy="0 0 0" xyz="0 0 -0.31"/>
      <geometry>
        <sphere radius="0.09"/>
      </geometry>
    </collision>
    <collision>
      <origin rpy="0 0 0" xyz="0 0 -0.21"/>
      <geometry>
        <sphere radius="0.09"/>
      </geometry>
    </collision>
    <collision>
      <origin rpy="0 0 0" xyz="0 0.08 -0.13"/>
      <geometry>
        <cylinder length="0.14" radius="0.055"/>
      </geometry>
    </collision>
    <collision>
      <origin rpy="0 0 0" xyz="0 0.08 -0.06"/>
      <geometry>
        <sphere radius="0.055"/>
      </geometry>
    </collision>
    <collision>
      <origin rpy="0 0 0" xyz="0 0.08 -0.20"/>
      <geometry>
        <sphere radius="0.055"/>
      </geometry>
    </collision>
  </link>
  <joint name="panda_joint5" type="revolute">
    <safety_controller k_position="100.0" k_velocity="40.0" soft_lower_limit="-2.8973" soft_upper_limit="2.8973"/>
    <origin rpy="-1.5707963267948966 0 0" xyz="-0.0825 0.384 0"/>
    <parent link="panda_link4"/>
    <child link="panda_link5"/>
    <axis xyz="0 0 1"/>
    <limit effort="12" lower="-2.8973" upper="2.8973" velocity="2.6100"/>
  </joint>
  <link name="panda_link6">
    <visual>
      <geometry>
        <mesh filename="package://moveit_resources_franka_panda_description/meshes/visual/link6.dae"/>
      </geometry>
    </visual>
    <collision>
      <origin rpy="0 0 0" xyz="0 0 -0.03"/>
      <geometry>
        <cylinder length="0.08" radius="0.08"/>
      </geometry>
    </collision>
    <collision>
      <origin rpy="0 0 0" xyz="0 0 0.01"/>
      <geometry>
        <sphere radius="0.08"/>
      </geometry>
    </collision>
    <collision>
      <origin rpy="0 0 0" xyz="0 0 -0.07"/>
      <geometry>
        <sphere radius="0.08"/>
      </geometry>
    </collision>
  </link>
  <joint name="panda_joint6" type="revolute">
    <safety_controller k_position="100.0" k_velocity="40.0" soft_lower_limit="-0.0175" soft_upper_limit="3.7525"/>
    <origin rpy="1.5707963267948966 0 0" xyz="0 0 0"/>
    <parent link="panda_link5"/>
    <child link="panda_link6"/>
    <axis xyz="0 0 1"/>
    <limit effort="12" lower="-0.0175" upper="3.7525" velocity="2.6100"/>
  </joint>
  <link name="panda_link7">
    <visual>
      <geometry>
        <mesh filename="package://moveit_resources_franka_panda_description/meshes/visual/link7.dae"/>
      </geometry>
    </visual>
    <collision>
      <origin rpy="0 0 0" xyz="0 0 0.01"/>
      <geometry>
        <cylinder length="0.14" radius="0.07"/>
      </geometry>
    </collision>
    <collision>
      <origin rpy="0 0 0" xyz="0 0 0.08"/>
      <geometry>
        <sphere radius="0.07"/>
      </geometry>
    </collision>
    <collision>
      <origin rpy="0 0 0" xyz="0 0 -0.06"/>
      <geometry>
        <sphere radius="0.07"/>
      </geometry>
    </collision>
  </link>
  <joint name="panda_joint7" type="revolute">
    <safety_controller k_position="100.0" k_velocity="40.0" soft_lower_limit="-2.8973" soft_upper_limit="2.8973"/>
    <origin rpy="1.5707963267948966 0 0" xyz="0.088 0 0"/>
    <parent link="panda_link6"/>
    <child link="panda_link7"/>
    <axis xyz="0 0 1"/>
    <limit effort="12" lower="-2.8973" upper="2.8973" velocity="2.6100"/>
  </joint>
  <link name="panda_link8">
    <collision>
      <origin rpy="3.141592653589793 1.5707963267948966 1.5707963267948966" xyz="0.0424 0.0424 -0.0250"/>
      <geometry>
        <cylinder length="0.01" radius="0.06"/>
      </geometry>
    </collision>
    <collision>
      <origin rpy="0 0 0" xyz="0.0424 0.0424 -0.02"/>
      <geometry>
        <sphere radius="0.06"/>
      </geometry>
    </collision>
    <collision>
      <origin rpy="0 0 0" xyz="0.0424 0.0424 -0.03"/>
      <geometry>
        <sphere radius="0.06"/>
      </geometry>
    </collision>
  </link>
  <joint name="panda_joint8" type="fixed">
    <origin rpy="0 0 0" xyz="0 0 0.107"/>
    <parent link="panda_link7"/>
    <child link="panda_link8"/>
  </joint>
  <ros2_control name="RobotiqGripperHardwareInterface" type="system">
    <!-- Plugins -->
    <hardware>
      <plugin>mock_components/GenericSystem</plugin>
      <param name="fake_sensor_commands">False</param>
      <param name="state_following_offset">0.0</param>
    </hardware>
    <!-- Joint interfaces -->
    <!-- With Ignition or Hardware, they handle mimic joints, so we only need this command interface activated -->
    <joint name="robotiq_85_left_knuckle_joint">
      <command_interface name="position"/>
      <state_interface name="position">
        <param name="initial_value">0.7929</param>
      </state_interface>
      <state_interface name="velocity"/>
    </joint>
    <joint name="robotiq_85_right_knuckle_joint">
      <param name="mimic">robotiq_85_left_knuckle_joint</param>
      <param name="multiplier">-1</param>
      <command_interface name="position"/>
      <state_interface name="position"/>
      <state_interface name="velocity"/>
    </joint>
    <joint name="robotiq_85_left_inner_knuckle_joint">
      <param name="mimic">robotiq_85_left_knuckle_joint</param>
      <param name="multiplier">1</param>
      <command_interface name="position"/>
      <state_interface name="position"/>
      <state_interface name="velocity"/>
    </joint>
    <joint name="robotiq_85_right_inner_knuckle_joint">
      <param name="mimic">robotiq_85_left_knuckle_joint</param>
      <param name="multiplier">-1</param>
      <command_interface name="position"/>
      <state_interface name="position"/>
      <state_interface name="velocity"/>
    </joint>
    <joint name="robotiq_85_left_finger_tip_joint">
      <param name="mimic">robotiq_85_left_knuckle_joint</param>
      <param name="multiplier">-1</param>
      <command_interface name="position"/>
      <state_interface name="position"/>
      <state_interface name="velocity"/>
    </joint>
    <joint name="robotiq_85_right_finger_tip_joint">
      <param name="mimic">robotiq_85_left_knuckle_joint</param>
      <param name="multiplier">1</param>
      <command_interface name="position"/>
      <state_interface name="position"/>
      <state_interface name="velocity"/>
    </joint>
    <gpio name="reactivate_gripper">
      <command_interface name="reactivate_gripper_cmd"/>
      <command_interface name="reactivate_gripper_response"/>
    </gpio>
  </ros2_control>
  <link name="robotiq_85_base_link">
    <visual>
      <geometry>
        <mesh filename="package://robotiq_description/meshes/visual/robotiq_base.dae"/>
      </geometry>
    </visual>
    <collision>
      <geometry>
        <mesh filename="package://robotiq_description/meshes/collision/robotiq_base.stl"/>
      </geometry>
    </collision>
    <inertial>
      <origin rpy="0 0 0" xyz="0.0 2.274e-05 0.03232288"/>
      <mass value="6.6320197e-01"/>
      <inertia ixx="5.1617816e-04" ixy="2.936e-8" ixz="0.0" iyy="5.8802208e-04" iyz="-3.2296e-7" izz="3.9462776e-04"/>
    </inertial>
  </link>
  <link name="robotiq_85_left_knuckle_link">
    <visual>
      <geometry>
        <mesh filename="package://robotiq_description/meshes/visual/left_knuckle.dae"/>
      </geometry>
    </visual>
    <collision>
      <geometry>
        <mesh filename="package://robotiq_description/meshes/collision/left_knuckle.stl"/>
      </geometry>
    </collision>
    <inertial>
      <origin rpy="0 0 0" xyz="0.01213197 0.0002 -0.00058647"/>
      <mass value="1.384773208e-02"/>
      <inertia ixx="3.5232e-7" ixy="0.0" ixz="1.1744e-7" iyy="2.31944e-6" iyz="0" izz="2.23136e-6"/>
    </inertial>
  </link>
  <link name="robotiq_85_right_knuckle_link">
    <visual>
      <geometry>
        <mesh filename="package://robotiq_description/meshes/visual/right_knuckle.dae"/>
      </geometry>
    </visual>
    <collision>
      <geometry>
        <mesh filename="package://robotiq_description/meshes/collision/right_knuckle.stl"/>
      </geometry>
    </collision>
    <inertial>
      <origin rpy="0 0 0" xyz="-0.01213197 0.0002 -0.00058647"/>
      <mass value="1.384773208e-02"/>
      <inertia ixx="3.5232e-7" ixy="0.0" ixz="-1.1744e-7" iyy="2.31944e-6" iyz="0.0" izz="2.23136e-6"/>
    </inertial>
  </link>
  <link name="robotiq_85_left_finger_link">
    <visual>
      <geometry>
        <mesh filename="package://robotiq_description/meshes/visual/left_finger.dae"/>
      </geometry>
    </visual>
    <collision>
      <geometry>
        <mesh filename="package://robotiq_description/meshes/collision/left_finger.stl"/>
      </geometry>
    </collision>
    <inertial>
      <origin rpy="0 0 0" xyz="0.00346899 -0.00079447 0.01867121"/>
      <mass value="4.260376752e-02"/>
      <inertia ixx="1.385792000000000e-05" ixy="0.0" ixz="-2.17264e-06" iyy="1.183208e-05" iyz="0.0" izz="5.19672e-06"/>
    </inertial>
  </link>
  <link name="robotiq_85_right_finger_link">
    <visual>
      <geometry>
        <mesh filename="package://robotiq_description/meshes/visual/right_finger.dae"/>
      </geometry>
    </visual>
    <collision>
      <geometry>
        <mesh filename="package://robotiq_description/meshes/collision/right_finger.stl"/>
      </geometry>
    </collision>
    <inertial>
      <origin rpy="0 0 0" xyz="-0.00346899 -5.53e-06 0.01867121"/>
      <mass value="4.260376752000000e-02"/>
      <inertia ixx="1.385792e-05" ixy="0.0" ixz="2.17264e-06" iyy="1.183208e-05" iyz="0.0" izz="5.19672e-06"/>
    </inertial>
  </link>
  <link name="robotiq_85_left_inner_knuckle_link">
    <visual>
      <geometry>
        <mesh filename="package://robotiq_description/meshes/visual/left_inner_knuckle.dae"/>
      </geometry>
    </visual>
    <collision>
      <geometry>
        <mesh filename="package://robotiq_description/meshes/collision/left_inner_knuckle.stl"/>
      </geometry>
    </collision>
    <inertial>
      <origin rpy="0 0 0" xyz="0.01897699 0.00015001 0.02247101"/>
      <mass value="2.969376448e-02"/>
      <inertia ixx="9.57136e-06" ixy="0.0" ixz="-3.93424e-06" iyy="8.69056e-06" iyz="0.0" izz="8.19144e-06"/>
    </inertial>
  </link>
  <link name="robotiq_85_right_inner_knuckle_link">
    <visual>
      <geometry>
        <mesh filename="package://robotiq_description/meshes/visual/right_inner_knuckle.dae"/>
      </geometry>
    </visual>
    <collision>
      <geometry>
        <mesh filename="package://robotiq_description/meshes/collision/right_inner_knuckle.stl"/>
      </geometry>
    </collision>
    <inertial>
      <origin rpy="0 0 0" xyz="-0.01926824 5.001e-05 0.02222178"/>
      <mass value="2.969376448e-02"/>
      <inertia ixx="9.42456e-06" ixy="0.0" ixz="3.9636e-06" iyy="8.69056e-06" iyz="0.0" izz="8.33824e-06"/>
    </inertial>
  </link>
  <link name="robotiq_85_left_finger_tip_link">
    <visual>
      <geometry>
        <mesh filename="package://robotiq_description/meshes/visual/left_finger_tip.dae"/>
      </geometry>
    </visual>
    <collision>
      <geometry>
        <mesh filename="package://robotiq_description/meshes/collision/left_finger_tip.stl"/>
      </geometry>
      <surface>
        <friction>
          <ode>
            <mu1>100000.0</mu1>
            <mu2>100000.0</mu2>
          </ode>
        </friction>
        <contact>
          <ode>
            <kp>1e+5</kp>
            <kd>1</kd>
            <soft_cfm>0</soft_cfm>
            <soft_erp>0.2</soft_erp>
            <minDepth>0.002</minDepth>
            <maxVel>0</maxVel>
          </ode>
        </contact>
      </surface>
    </collision>
    <inertial>
      <origin rpy="0 0 0" xyz="-0.01456706 -0.0008 0.01649701"/>
      <mass value="4.268588744e-02"/>
      <inertia ixx="1.048152e-05" ixy="0.0" ixz="3.5232e-6" iyy="1.197888e-05" iyz="0.0" izz="4.22784e-06"/>
    </inertial>
  </link>
  <link name="robotiq_85_right_finger_tip_link">
    <visual>
      <geometry>
        <mesh filename="package://robotiq_description/meshes/visual/right_finger_tip.dae"/>
      </geometry>
    </visual>
    <collision>
      <geometry>
        <mesh filename="package://robotiq_description/meshes/collision/right_finger_tip.stl"/>
      </geometry>
      <surface>
        <friction>
          <ode>
            <mu1>100000.0</mu1>
            <mu2>100000.0</mu2>
          </ode>
        </friction>
        <contact>
          <ode>
            <kp>1e+5</kp>
            <kd>1</kd>
            <soft_cfm>0</soft_cfm>
            <soft_erp>0.2</soft_erp>
            <minDepth>0.002</minDepth>
            <maxVel>0</maxVel>
          </ode>
        </contact>
      </surface>
    </collision>
    <inertial>
      <origin rpy="0 0 0" xyz="0.01456706 5e-05 0.01649701"/>
      <mass value="4.268588744e-02"/>
      <inertia ixx="1.048152e-05" ixy="0.0" ixz="-3.5232e-06" iyy="1.197888e-05" iyz="0.0" izz="4.22784e-06"/>
    </inertial>
  </link>
  <joint name="robotiq_85_base_joint" type="fixed">
    <parent link="panda_link8"/>
    <child link="robotiq_85_base_link"/>
    <origin rpy="0 0 -0.7853981633974483" xyz="0 0 0"/>
  </joint>
  <joint name="robotiq_85_left_knuckle_joint" type="revolute">
    <parent link="robotiq_85_base_link"/>
    <child link="robotiq_85_left_knuckle_link"/>
    <axis xyz="0 -1 0"/>
    <origin rpy="0 0 0" xyz="0.03060114 0.0 0.05490452"/>
    <limit effort="50" lower="0.0" upper="0.8" velocity="0.5"/>
  </joint>
  <joint name="robotiq_85_right_knuckle_joint" type="revolute">
    <parent link="robotiq_85_base_link"/>
    <child link="robotiq_85_right_knuckle_link"/>
    <axis xyz="0 -1 0"/>
    <origin rpy="0 0 0" xyz="-0.03060114 0.0 0.05490452"/>
    <limit effort="50" lower="-0.8" upper="0.0" velocity="0.5"/>
    <mimic joint="robotiq_85_left_knuckle_joint" multiplier="-1"/>
  </joint>
  <joint name="robotiq_85_left_finger_joint" type="fixed">
    <parent link="robotiq_85_left_knuckle_link"/>
    <child link="robotiq_85_left_finger_link"/>
    <origin rpy="0 0 0" xyz="0.03152616 0.0 -0.00376347"/>
  </joint>
  <joint name="robotiq_85_right_finger_joint" type="fixed">
    <parent link="robotiq_85_right_knuckle_link"/>
    <child link="robotiq_85_right_finger_link"/>
    <origin rpy="0 0 0" xyz="-0.03152616 0.0 -0.00376347"/>
  </joint>
  <joint name="robotiq_85_left_inner_knuckle_joint" type="continuous">
    <parent link="robotiq_85_base_link"/>
    <child link="robotiq_85_left_inner_knuckle_link"/>
    <axis xyz="0 -1 0"/>
    <origin rpy="0 0 0" xyz="0.0127 0.0 0.06142"/>
    <mimic joint="robotiq_85_left_knuckle_joint"/>
  </joint>
  <joint name="robotiq_85_right_inner_knuckle_joint" type="continuous">
    <parent link="robotiq_85_base_link"/>
    <child link="robotiq_85_right_inner_knuckle_link"/>
    <axis xyz="0 -1 0"/>
    <origin rpy="0 0 0" xyz="-0.0127 0.0 0.06142"/>
    <mimic joint="robotiq_85_left_knuckle_joint" multiplier="-1"/>
  </joint>
  <joint name="robotiq_85_left_finger_tip_joint" type="continuous">
    <parent link="robotiq_85_left_finger_link"/>
    <child link="robotiq_85_left_finger_tip_link"/>
    <axis xyz="0 -1 0"/>
    <origin rpy="0 0 0" xyz="0.00563134 0.0 0.04718515"/>
    <mimic joint="robotiq_85_left_knuckle_joint" multiplier="-1"/>
  </joint>
  <joint name="robotiq_85_right_finger_tip_joint" type="continuous">
    <parent link="robotiq_85_right_finger_link"/>
    <child link="robotiq_85_right_finger_tip_link"/>
    <axis xyz="0 -1 0"/>
    <origin rpy="0 0 0" xyz="-0.00563134 0.0 0.04718515"/>
    <mimic joint="robotiq_85_left_knuckle_joint"/>
  </joint>
  <!-- Add an additional link to plan with. Oriented like the Panda ee_link frame. -->
  <joint name="robotiq_gripper_tip_link_joint" type="fixed">
    <parent link="robotiq_85_base_link"/>
    <child link="robotiq_gripper_tip_link"/>
    <origin rpy="0.0 0.0 0.0" xyz="0.0 0.0 0.16"/>
  </joint>
  <link name="robotiq_gripper_tip_link"/>
  <ros2_control name="FrankaHardwareInterface" type="system">
    <hardware>
      <plugin>fake_components/GenericSystem</plugin>
      <param name="fake_sensor_commands">True</param>
      <param name="state_following_offset">0.0</param>
    </hardware>
    <joint name="panda_joint1">
      <param name="initial_position">0.0</param>
      <command_interface name="effort"/>
      <state_interface name="position"/>
      <state_interface name="velocity"/>
      <state_interface name="effort"/>
    </joint>
    <joint name="panda_joint2">
      <param name="initial_position">-0.7853981633974483</param>
      <command_interface name="effort"/>
      <state_interface name="position"/>
      <state_interface name="velocity"/>
      <state_interface name="effort"/>
    </joint>
    <joint name="panda_joint3">
      <param name="initial_position">0.0</param>
      <command_interface name="effort"/>
      <state_interface name="position"/>
      <state_interface name="velocity"/>
      <state_interface name="effort"/>
    </joint>
    <joint name="panda_joint4">
      <param name="initial_position">-2.356194490192345</param>
      <command_interface name="effort"/>
      <state_interface name="position"/>
      <state_interface name="velocity"/>
      <state_interface name="effort"/>
    </joint>
    <joint name="panda_joint5">
      <param name="initial_position">0.0</param>
      <command_interface name="effort"/>
      <state_interface name="position"/>
      <state_interface name="velocity"/>
      <state_interface name="effort"/>
    </joint>
    <joint name="panda_joint6">
      <param name="initial_position">1.5707963267948966</param>
      <command_interface name="effort"/>
      <state_interface name="position"/>
      <state_interface name="velocity"/>
      <state_interface name="effort"/>
    </joint>
    <joint name="panda_joint7">
      <param name="initial_position">0.7853981633974483</param>
      <command_interface name="effort"/>
      <state_interface name="position"/>
      <state_interface name="velocity"/>
      <state_interface name="effort"/>
    </joint>
  </ros2_control>
</robot>
